Workbook

Sheet igsr_samples
A1: Sample name | B1: Sex | C1: Biosample ID | D1: Population code | E1: Population name | F1: Superpopulation code | G1: correct | H1: Superpop_code_self | I1: Superpopulation name | J1: Population elastic ID | K1: Data collections
A2: HG00152 | B2: male | C2: SAME124593 | D2: GBR | E2: British | F2: EUR | G2: =IF(F2=H2,1,0) -> 1 | H2: =VLOOKUP(J2,Sheet3!I:J,2,0) -> EUR | I2: European Ancestry | J2: GBR | K2: 1000 Genomes on GRCh38,1KG_ONT_VIENNA,1000 Genomes phase 3 release,1000 Genomes phase 1 release,Geuvadis
A3: HG00157 | B3: male | C3: SAME124590 | D3: GBR | E3: British | F3: EUR | G3: =IF(F3=H3,1,0) -> 1 | H3: =VLOOKUP(J3,Sheet3!I:J,2,0) -> EUR | I3: European Ancestry | J3: GBR | K3: 1000 Genomes on GRCh38,1000 Genomes 30x on GRCh38,1KG_ONT_VIENNA,1000 Genomes phase 3 release,1000 Genomes phase 1 release,Geuvadis
A4: HG00171 | B4: female | C4: SAME124961 | D4: FIN | E4: Finnish | F4: EUR | G4: =IF(F4=H4,1,0) -> 1 | H4: =VLOOKUP(J4,Sheet3!I:J,2,0) -> EUR | I4: European Ancestry | J4: FIN | K4: 1000 Genomes on GRCh38,1000 Genomes 30x on GRCh38,Human Genome Structural Variation Consortium, Phase 2,Human Genome Structural Variation Consortium, Phase 3,1KG_ONT_VIENNA,1000 Genomes phase 3 release,1000 Genomes phase 1 release,Geuvadis
A5: HG00176 | B5: female | C5: SAME124956 | D5: FIN | E5: Finnish | F5: EUR | G5: =IF(F5=H5,1,0) -> 1 | H5: =VLOOKUP(J5,Sheet3!I:J,2,0) -> EUR | I5: European Ancestry | J5: FIN | K5: 1000 Genomes on GRCh38,1000 Genomes 30x on GRCh38,1000 Genomes phase 3 release,1000 Genomes phase 1 release,Geuvadis
A6: HG00183 | B6: male | C6: SAME123642 | D6: FIN | E6: Finnish | F6: EUR | G6: =IF(F6=H6,1,0) -> 1 | H6: =VLOOKUP(J6,Sheet3!I:J,2,0) -> EUR | I6: European Ancestry | J6: FIN | K6: 1000 Genomes on GRCh38,1000 Genomes 30x on GRCh38,MAGE RNA-seq,1000 Genomes phase 3 release,1000 Genomes phase 1 release,Geuvadis
A7: HG00188 | B7: male | C7: SAME123641 | D7: FIN | E7: Finnish | F7: EUR | G7: =IF(F7=H7,1,0) -> 1 | H7: =VLOOKUP(J7,Sheet3!I:J,2,0) -> EUR | I7: European Ancestry | J7: FIN | K7: 1000 Genomes on GRCh38,1000 Genomes 30x on GRCh38,1KG_ONT_VIENNA,MAGE RNA-seq,1000 Genomes phase 3 release,1000 Genomes phase 1 release,Geuvadis
A8: HG00190 | B8: male | C8: SAME123856 | D8: FIN | E8: Finnish,Finnish | F8: EUR | G8: =IF(F8=H8,1,0) -> 1 | H8: =VLOOKUP(J8,Sheet3!I:J,2,0) -> EUR | I8: European Ancestry,West Eurasia (SGDP) | J8: FIN,FinnishSGDP | K8: 1000 Genomes on GRCh38,Simons Genome Diversity Project,1000 Genomes 30x on GRCh38,1KG_ONT_VIENNA,MAGE RNA-seq,1000 Genomes phase 3 release,1000 Genomes phase 1 release
A9: HG00234 | B9: male | C9: SAME124123 | D9: GBR | E9: British | F9: EUR | G9: =IF(F9=H9,1,0) -> 1 | H9: =VLOOKUP(J9,Sheet3!I:J,2,0) -> EUR | I9: European Ancestry | J9: GBR | K9: 1000 Genomes on GRCh38,1000 Genomes 30x on GRCh38,1000 Genomes phase 3 release,1000 Genomes phase 1 release,Geuvadis
A10: HG00239 | B10: female | C10: SAME124130 | D10: GBR | E10: British | F10: EUR | G10: =IF(F10=H10,1,0) -> 1 | H10: =VLOOKUP(J10,Sheet3!I:J,2,0) -> EUR | I10: European Ancestry | J10: GBR | K10: 1000 Genomes on GRCh38,1000 Genomes 30x on GRCh38,1000 Genomes phase 3 release,1000 Genomes phase 1 release,Geuvadis
A11: HG00246 | B11: male | C11: SAME123219 | D11: GBR | E11: British | F11: EUR | G11: =IF(F11=H11,1,0) -> 1 | H11: =VLOOKUP(J11,Sheet3!I:J,2,0) -> EUR | I11: European Ancestry | J11: GBR | K11: 1000 Genomes on GRCh38,1000 Genomes 30x on GRCh38,1000 Genomes phase 3 release,1000 Genomes phase 1 release,Geuvadis
A12: HG00253 | B12: female | C12: SAME123051 | D12: GBR | E12: British | F12: EUR | G12: =IF(F12=H12,1,0) -> 1 | H12: =VLOOKUP(J12,Sheet3!I:J,2,0) -> EUR | I12: European Ancestry | J12: GBR | K12: 1000 Genomes on GRCh38,1000 Genomes 30x on GRCh38,Human Pangenome Reference Consortium, Phase 2,1000 Genomes phase 3 release,1000 Genomes phase 1 release,Geuvadis
A13: HG00258 | B13: female | C13: SAME123057 | D13: GBR | E13: British | F13: EUR | G13: =IF(F13=H13,1,0) -> 1 | H13: =VLOOKUP(J13,Sheet3!I:J,2,0) -> EUR | I13: European Ancestry | J13: GBR | K13: 1000 Genomes on GRCh38,1000 Genomes 30x on GRCh38,1KG_ONT_VIENNA,Human Pangenome Reference Consortium, Phase 2,1000 Genomes phase 3 release,1000 Genomes phase 1 release,Geuvadis
... A67: HG00626 | B67: female | C67: SAME123078 | D67: CHS | E67: Southern Han Chinese | F67: EAS | G67: =IF(F67=H67,1,0) -> 1 | H67: =VLOOKUP(J67,Sheet3!I:J,2,0) -> EAS | I67: East Asian Ancestry | J67: CHS | K67: 1000 Genomes on GRCh38,1000 Genomes 30x on GRCh38,1KG_ONT_VIENNA,1000 Genomes phase 3 release,1000 Genomes phase 1 release
A68: HG00633 | B68: male | C68: SAME1839144 | D68: CHS | E68: Southern Han Chinese | F68: EAS | G68: =IF(F68=H68,1,0) -> 1 | H68: =VLOOKUP(J68,Sheet3!I:J,2,0) -> EAS | I68: East Asian Ancestry | J68: CHS
A69: HG00638 | B69: female | C69: SAME123652 | D69: PUR | E69: Puerto Rican | F69: AMR | G69: =IF(F69=H69,1,0) -> 1 | H69: =VLOOKUP(J69,Sheet3!I:J,2,0) -> AMR | I69: American Ancestry | J69: PUR | K69: 1000 Genomes on GRCh38,1000 Genomes 30x on GRCh38,1000 Genomes phase 3 release,1000 Genomes phase 1 release
A70: HG00640 | B70: male | C70: SAME123434 | D70: PUR | E70: Puerto Rican | F70: AMR | G70: =IF(F70=H70,1,0) -> 1 | H70: =VLOOKUP(J70,Sheet3!I:J,2,0) -> AMR | I70: American Ancestry | J70: PUR | K70: 1000 Genomes on GRCh38,1000 Genomes 30x on GRCh38,1000 Genomes phase 3 release,1000 Genomes phase 1 release
A71: HG00652 | B71: female | C71: SAME123252 | D71: CHS | E71: Southern Han Chinese | F71: EAS | G71: =IF(F71=H71,1,0) -> 1 | H71: =VLOOKUP(J71,Sheet3!I:J,2,0) -> EAS | I71: East Asian Ancestry | J71: CHS | K71: 1000 Genomes 30x on GRCh38,1000 Genomes phase 3 release
A72: HG00657 | B72: female | C72: SAME123255 | D72: CHS | E72: Southern Han Chinese | F72: EAS | G72: =IF(F72=H72,1,0) -> 1 | H72: =VLOOKUP(J72,Sheet3!I:J,2,0) -> EAS | I72: East Asian Ancestry | J72: CHS | K72: 1000 Genomes on GRCh38,1000 Genomes 30x on GRCh38,1KG_ONT_VIENNA,MAGE RNA-seq,1000 Genomes phase 3 release,1000 Genomes phase 1 release,90 Han Chinese high coverage genomes
A73: HG00664 | B73: male | C73: SAME123814 | D73: CHS | E73: Southern Han Chinese | F73: EAS | G73: =IF(F73=H73,1,0) -> 1 | H73: =VLOOKUP(J73,Sheet3!I:J,2,0) -> EAS | I73: East Asian Ancestry | J73: CHS | K73: 1000 Genomes 30x on GRCh38,1000 Genomes phase 3 release
A74: HG00671 | B74: male | C74: SAME123604 | D74: CHS | E74: Southern Han Chinese | F74: EAS | G74: =IF(F74=H74,1,0) -> 1 | H74: =VLOOKUP(J74,Sheet3!I:J,2,0) -> EAS | I74: East Asian Ancestry | J74: CHS | K74: 1000 Genomes on GRCh38,1000 Genomes 30x on GRCh38,1000 Genomes phase 3 release,1000 Genomes phase 1 release,90 Han Chinese high coverage genomes
A75: HG00676 | B75: male | C75: SAME1840071 | D75: CHS | E75: Southern Han Chinese | F75: EAS | G75: =IF(F75=H75,1,0) -> 1 | H75: =VLOOKUP(J75,Sheet3!I:J,2,0) -> EAS | I75: East Asian Ancestry | J75: CHS
A76: HG00683 | B76: male | C76: SAME123892 | D76: CHS | E76: Southern Han Chinese | F76: EAS | G76: =IF(F76=H76,1,0) -> 1 | H76: =VLOOKUP(J76,Sheet3!I:J,2,0) -> EAS | I76: East Asian Ancestry | J76: CHS | K76: 1000 Genomes on GRCh38,1000 Genomes 30x on GRCh38,1000 Genomes phase 3 release,1000 Genomes phase 1 release,90 Han Chinese high coverage genomes
A77: HG00690 | B77: female | C77: SAME123686 | D77: CHS | E77: Southern Han Chinese | F77: EAS | G77: =IF(F77=H77,1,0) -> 1 | H77: =VLOOKUP(J77,Sheet3!I:J,2,0) -> EAS | I77: East Asian Ancestry | J77: CHS | K77: 1000 Genomes on GRCh38,1000 Genomes 30x on GRCh38,1000 Genomes phase 3 release,1000 Genomes phase 1 release,90 Han Chinese high coverage genomes
A78: HG00703 | B78: male | C78: SAME122933 | D78: CHS | E78: Southern Han Chinese | F78: EAS | G78: =IF(F78=H78,1,0) -> 1 | H78: =VLOOKUP(J78,Sheet3!I:J,2,0) -> EAS | I78: East Asian Ancestry | J78: CHS | K78: 1000 Genomes 30x on GRCh38,1000 Genomes phase 3 release
A79: HG00708 | B79: female | C79: SAME122940 | D79: CHS | E79: Southern Han Chinese | F79: EAS | G79: =IF(F79=H79,1,0) -> 1 | H79: =VLOOKUP(J79,Sheet3!I:J,2,0) -> EAS | I79: East Asian Ancestry | J79: CHS | K79: 1000 Genomes on GRCh38,1000 Genomes 30x on GRCh38,1000 Genomes phase 3 release,1000 Genomes phase 1 release
A80: HG01516 | B80: female | C80: SAME124773 | D80: IBS | E80: Iberian | F80: EUR | G80: =IF(F80=H80,1,0) -> 1 | H80: =VLOOKUP(J80,Sheet3!I:J,2,0) -> EUR | I80: European Ancestry | J80: IBS | K80: 1000 Genomes on GRCh38,1000 Genomes 30x on GRCh38,1000 Genomes phase 3 release,1000 Genomes phase 1 release
A81: HG01523 | B81: male | C81: SAME125322 | D81: IBS | E81: Iberian | F81: EUR | G81: =IF(F81=H81,1,0) -> 1 | H81: =VLOOKUP(J81,Sheet3!I:J,2,0) -> EUR | I81: European Ancestry | J81: IBS | K81: 1000 Genomes 30x on GRCh38,1000 Genomes phase 3 release
A82: HG01528 | B82: female | C82: SAME125329 | D82: IBS | E82: Iberian | F82: EUR | G82: =IF(F82=H82,1,0) -> 1 | H82: =VLOOKUP(J82,Sheet3!I:J,2,0) -> EUR | I82: European Ancestry | J82: IBS | K82: 1000 Genomes on GRCh38,1000 Genomes 30x on GRCh38,1000 Genomes phase 3 release
A83: HG01530 | B83: male | C83: SAME125137 | D83: IBS | E83: Iberian | F83: EUR | G83: =IF(F83=H83,1,0) -> 1 | H83: =VLOOKUP(J83,Sheet3!I:J,2,0) -> EUR | I83: European Ancestry | J83: IBS | K83: 1000 Genomes on GRCh38,1000 Genomes 30x on GRCh38,1KG_ONT_VIENNA,Human Pangenome Reference Consortium, Phase 2,1000 Genomes phase 3 release
A84: HG01566 | B84: female | C84: SAME124564 | D84: PEL | E84: Peruvian | F84: AMR | G84: =IF(F84=H84,1,0) -> 1 | H84: =VLOOKUP(J84,Sheet3!I:J,2,0) -> AMR | I84: American Ancestry | J84: PEL | K84: 1000 Genomes on GRCh38,1000 Genomes 30x on GRCh38,1KG_ONT_VIENNA,1000 Genomes phase 3 release
A85: HG01573 | B85: female | C85: SAME124347 | D85: PEL | E85: Peruvian | F85: AMR | G85: =IF(F85=H85,1,0) -> 1 | H85: =VLOOKUP(J85,Sheet3!I:J,2,0) -> AMR | I85: American Ancestry | J85: PEL | K85: 1000 Genomes 30x on GRCh38,Human Genome Structural Variation Consortium, Phase 2,Human Genome Structural Variation Consortium, Phase 3,1000 Genomes phase 3 release
A86: HG01578 | B86: female | C86: SAME124351 | D86: PEL | E86: Peruvian | F86: AMR | G86: =IF(F86=H86,1,0) -> 1 | H86: =VLOOKUP(J86,Sheet3!I:J,2,0) -> AMR | I86: American Ancestry | J86: PEL | K86: 1000 Genomes on GRCh38,1000 Genomes 30x on GRCh38,1KG_ONT_VIENNA,MAGE RNA-seq,1000 Genomes phase 3 release
A87: HG01597 | B87: female | C87: SAME125226 | D87: KHV | E87: Kinh Vietnamese | F87: EAS | G87: =IF(F87=H87,1,0) -> 1 | H87: =VLOOKUP(J87,Sheet3!I:J,2,0) -> EAS | I87: East Asian Ancestry | J87: KHV | K87: 1000 Genomes on GRCh38,1000 Genomes 30x on GRCh38,1KG_ONT_VIENNA,MAGE RNA-seq,1000 Genomes phase 3 release
... A169: HG02235 | B169: female | C169: SAME123521 | D169: IBS | E169: Iberian | F169: EUR | G169: =IF(F169=H169,1,0) -> 1 | H169: =VLOOKUP(J169,Sheet3!I:J,2,0) -> EUR | I169: European Ancestry | J169: IBS | K169: 1000 Genomes on GRCh38,1000 Genomes 30x on GRCh38,1000 Genomes phase 3 release
A170: HG02254 | B170: female | C170: SAME1839344 | D170: PEL | E170: Peruvian | F170: AMR | G170: =IF(F170=H170,1,0) -> 1 | H170: =VLOOKUP(J170,Sheet3!I:J,2,0) -> AMR | I170: American Ancestry | J170: PEL
A171: HG02259 | B171: male | C171: SAME1839319 | D171: PEL | E171: Peruvian | F171: AMR | G171: =IF(F171=H171,1,0) -> 1 | H171: =VLOOKUP(J171,Sheet3!I:J,2,0) -> AMR | I171: American Ancestry | J171: PEL | K171: 1000 Genomes on GRCh38,1000 Genomes 30x on GRCh38,1000 Genomes phase 3 release
A172: HG02261 | B172: male | C172: SAME1839134 | D172: PEL | E172: Peruvian | F172: AMR | G172: =IF(F172=H172,1,0) -> 1 | H172: =VLOOKUP(J172,Sheet3!I:J,2,0) -> AMR | I172: American Ancestry | J172: PEL | K172: 1000 Genomes 30x on GRCh38,1000 Genomes phase 3 release
A173: HG02266 | B173: female | C173: SAME1839110 | D173: PEL | E173: Peruvian | F173: AMR | G173: =IF(F173=H173,1,0) -> 1 | H173: =VLOOKUP(J173,Sheet3!I:J,2,0) -> AMR | I173: American Ancestry | J173: PEL | K173: 1000 Genomes on GRCh38,1000 Genomes 30x on GRCh38,1KG_ONT_VIENNA,1000 Genomes phase 3 release
A174: HG02273 | B174: female | C174: SAME1840309 | D174: PEL | E174: Peruvian | F174: AMR | G174: =IF(F174=H174,1,0) -> 1 | H174: =VLOOKUP(J174,Sheet3!I:J,2,0) -> AMR | I174: American Ancestry | J174: PEL | K174: 1000 Genomes 30x on GRCh38,Human Pangenome Reference Consortium, Phase 2,1000 Genomes phase 3 release
...

Sheet Sheet2
A1: Superpopulation name | B1: Population elastic ID
A2: European Ancestry | B2: GBR
A3: European Ancestry | B3: GBR
A4: European Ancestry | B4: FIN
A5: European Ancestry | B5: FIN
A6: European Ancestry | B6: FIN
A7: European Ancestry | B7: FIN
A8: European Ancestry,West Eurasia (SGDP) | B8: FIN,FinnishSGDP
A9: European Ancestry | B9: GBR
A10: European Ancestry | B10: GBR
A11: European Ancestry | B11: GBR
A12: European Ancestry | B12: GBR
... A4990: African Ancestry | B4990: YRI

Sheet Sheet3
B1: Superpopulation name | C1: Population elastic ID | H1: Superpopulation name | I1: Population elastic ID | J1: Superpopulation Code
B2: European Ancestry | C2: GBR | G2: =IF(C2=I2,1,0) -> 0 | H2: Africa (HGDP) | I2: MbutiHGDP | J2: AFR
B3: European Ancestry | C3: FIN | G3: =IF(C3=I3,1,0) -> 0 | H3: Africa (HGDP) | I3: BiakaHGDP | J3: AFR
B4: European Ancestry,West Eurasia (SGDP) | C4: FIN,FinnishSGDP | G4: =IF(C4=I4,1,0) -> 0 | H4: Africa (HGDP) | I4: MandenkaHGDP | J4: AFR
B5: East Asian Ancestry | C5: CHS | G5: =IF(C5=I5,1,0) -> 0 | H5: Africa (HGDP) | I5: YorubaHGDP | J5: AFR
B6: European Ancestry,West Eurasia (SGDP) | C6: GBR,EnglishSGDP | G6: =IF(C6=I6,1,0) -> 0 | H6: Africa (HGDP) | I6: BantuSouthAfricaHGDP | J6: AFR
B7: American Ancestry | C7: PUR | G7: =IF(C7=I7,1,0) -> 0 | H7: Africa (HGDP) | I7: BantuKenyaHGDP | J7: AFR
B8: European Ancestry | C8: IBS | G8: =IF(C8=I8,1,0) -> 0 | H8: Africa (HGDP) | I8: SanHGDP | J8: AFR
B9: American Ancestry | C9: PEL | G9: =IF(C9=I9,1,0) -> 0 | H9: Africa (SGDP) | I9: Masai | J9: AFR
B10: East Asian Ancestry | C10: KHV | G10: =IF(C10=I10,1,0) -> 0 | H10: Africa (SGDP) | I10: BantuHereroSGDP | J10: AFR
B11: East Asia (SGDP),East Asian Ancestry | C11: KinhSGDP,KHV | G11: =IF(C11=I11,1,0) -> 0 | H11: Africa (SGDP) | I11: KhomaniSanSGDP | J11: AFR
B12: African Ancestry | C12: ACB | G12: =IF(C12=I12,1,0) -> 0 | H12: Africa (SGDP) | I12: SaharawiSGDP | J12: AFR
B13: East Asian Ancestry | C13: CDX | G13: =IF(C13=I13,1,0) -> 0 | H13: Africa (SGDP) | I13: YorubaSGDP | J13: AFR
... B221: West Eurasia (SGDP) | C221: NorwegianSGDP | G221: =IF(C221=I221,1,0) -> 1 | H221: West Eurasia (SGDP) | I221: NorwegianSGDP | J221: EUR

Sheet Sheet4
A1: AFR Africa | B1: 19 populations groups | E1: https://www.genome.dating/ancestry/B_Han-3
B2: Bantu Herero | C2: 2
B3: Bantu Kenya | C3: 2
B4: Bantu Tswana | C4: 2
B5: Biaka | C5: 2
B6: Dinka | C6: 3
B7: Esan | C7: 2
B8: Gambian | C8: 2
B9: Ju-hoan North | C9: 4
B10: Khomani San | C10: 2
B11: Luhya | C11: 2
B12: Luo | C12: 2
B13: Masai | C13: 2
... B20: Yoruba | C20: 3
A21: AMR America | B21: 10 populations groups
B22: Chane | C22: 1
B23: Karitiana | C23: 3
B24: Mayan | C24: 2
B25: Mixe | C25: 3
B26: Mixtec | C26: 2
B27: Piapoco | C27: 2
B28: Pima | C28: 2
B29: Quechua | C29: 3
B30: Surui | C30: 2
B31: Zapotec | C31: 2
A32: CAS Central Asia Siberia | B32: 15 populations groups
B33: Aleut | C33: 2
B34: Altaian | C34: 1
B35: Chukchi | C35: 1
B36: Eskimo Chaplin | C36: 1
B37: Eskimo Naukan | C37: 2
B38: Eskimo Sireniki | C38: 2
B39: Even | C39: 3
B40: Itelman | C40: 1
B41: Kyrgyz | C41: 2
B42: Mansi | C42: 2
B43: Mongola | C43: 2
B44: Tubalar | C44: 2
... B47: Yakut | C47: 2
A48: EAS East Asia | B48: 22 populations groups
...
