Workbook

Sheet Tabelle1
A1: #Sequencing_Panel | B1: Illumina_ID | C1: Sample_ID | D1: Sample_ID(Aliases) | E1: SGDP_ID | F1: Population_ID | G1: Region | H1: Country | I1: Town | J1: Contributor | K1: Gender | L1: Latitude | M1: Longitude | N1: DNA_Source | O1: Embargo | P1: SGDP-lite category: X=FullyPublic | Q1: BiosampleID
A2: B | B2: SS6004478 | C2: IHW9118 | D2: IHW9118 | E2: B_Australian-3 | F2: Australian | G2: Oceania | H2: Australia | I2: Cell_line_repository_sampling_location_unknown | J2: ECCAC | K2: U | L2: -13 | M2: 143 | N2: Genomic_from_cell_lines | O2: FullyPublic | P2: X | Q2: =VLOOKUP(B2,Tabelle2!C:S,17,0) -> 0
A3: B | B3: SS6004477 | C3: IHW9193 | D3: IHW9193 | E3: B_Australian-4 | F3: Australian | G3: Oceania | H3: Australia | I3: Cell_line_repository_sampling_location_unknown | J3: ECCAC | K3: M | L3: -13 | M3: 143 | N3: Genomic_from_cell_lines | O3: FullyPublic | P3: X | Q3: =VLOOKUP(B3,Tabelle2!C:S,17,0) -> 0
A4: B | B4: LP6007069-DNA_A01 | C4: AV-21 | D4: AV-21 | E4: B_Crete-1 | F4: Crete | G4: WestEurasia | H4: Greece | I4: Preveliana | Q4: =VLOOKUP(B4,Tabelle2!C:S,17,0) -> 0
A5: B | B5: LP6007068-DNA_A01 | C5: TZ-11 | D5: TZ-11 | E5: B_Crete-2 | F5: Crete | G5: WestEurasia | H5: Greece | I5: Psychro | Q5: =VLOOKUP(B5,Tabelle2!C:S,17,0) -> 0
A6: B | B6: SS6004467 | C6: HGDP01308 | D6: HGDP01308 | E6: B_Dai-4 | F6: Dai | G6: EastAsia | H6: China | I6: ? | J6: Howard Cann | K6: M | L6: 21 | M6: 100 | N6: Genomic_from_cell_lines | O6: FullyPublic | P6: X | Q6: =VLOOKUP(B6,Tabelle2!C:S,17,0) -> 0
A7: B | B7: SS6004480 | C7: DNK07 | D7: DNK07 | E7: B_Dinka-3 | F7: Dinka | G7: Africa | H7: Sudan | I7: Aweil | J7: Michael Hammer | K7: M | L7: 8.7833333 | M7: 27.4 | N7: Genomic_from_saliva | O7: FullyPublic | P7: X | Q7: =VLOOKUP(B7,Tabelle2!C:S,17,0) -> 0
A8: B | B8: SS6004468 | C8: HGDP00533 | D8: HGDP00533 | E8: B_French-3 | F8: French | G8: WestEurasia | H8: France | I8: ? | J8: Howard Cann | K8: M | L8: 46 | M8: 2 | N8: Genomic_from_cell_lines | O8: FullyPublic | P8: X | Q8: =VLOOKUP(B8,Tabelle2!C:S,17,0) -> 0
A9: B | B9: SS6004469 | C9: HGDP00775 | D9: HGDP00775 | E9: B_Han-3 | F9: Han | G9: EastAsia | H9: China | I9: ? | J9: Howard Cann | K9: M | L9: 32.265668 | M9: 114 | N9: Genomic_from_cell_lines | O9: FullyPublic | P9: X | Q9: =VLOOKUP(B9,Tabelle2!C:S,17,0) -> 0
A10: B | B10: SS6004473 | C10: HGDP01036 | D10: HGDP01036 | E10: B_Ju_hoan_North-4 | F10: Ju_hoan_North | G10: Africa | H10: Namibia | I10: ? | J10: Howard Cann | K10: M | L10: -18.937257 | M10: 21.452448 | N10: Genomic_from_cell_lines | O10: FullyPublic | P10: X | Q10: =VLOOKUP(B10,Tabelle2!C:S,17,0) -> 0
A11: B | B11: SS6004476 | C11: HGDP01015 | D11: HGDP01015 | E11: B_Karitiana-3 | F11: Karitiana | G11: America | H11: Brazil | I11: ? | J11: Howard Cann | K11: M | L11: -10 | M11: -63 | N11: Genomic_from_cell_lines | O11: FullyPublic | P11: X | Q11: =VLOOKUP(B11,Tabelle2!C:S,17,0) -> 0
A12: B | B12: SS6004470 | C12: HGDP01286 | D12: HGDP01286 | E12: B_Mandenka-3 | F12: Mandenka | G12: Africa | H12: Senegal | I12: ? | J12: Howard Cann | K12: M | L12: 12 | M12: -12 | N12: Genomic_from_cell_lines | O12: FullyPublic | P12: X | Q12: =VLOOKUP(B12,Tabelle2!C:S,17,0) -> 0
A13: B | B13: SS6004471 | C13: HGDP00982 | D13: HGDP00982 | E13: B_Mbuti-4 | F13: Mbuti | G13: Africa | H13: Congo | I13: ? | J13: Howard Cann | K13: M | L13: 1 | M13: 29 | N13: Genomic_from_cell_lines | O13: FullyPublic | P13: X | Q13: =VLOOKUP(B13,Tabelle2!C:S,17,0) -> 0
A14: B | B14: SS6004479 | C14: mixe0007 | D14: mixe0007 | E14: B_Mixe-1 | F14: Mixe | G14: America | H14: Mexico | I14: Tmazulapan | Q14: =VLOOKUP(B14,Tabelle2!C:S,17,0) -> 0
A15: B | B15: SS6004472 | C15: HGDP00546 | D15: HGDP00546 | E15: B_Papuan-15 | F15: Papuan | G15: Oceania | H15: PapuaNewGuinea | I15: ? | J15: Howard Cann | K15: M | L15: -4 | M15: 143 | N15: Genomic_from_cell_lines | O15: FullyPublic | P15: X | Q15: =VLOOKUP(B15,Tabelle2!C:S,17,0) -> 0
A16: B | B16: SS6004474 | C16: HGDP01076 | D16: HGDP01076 | E16: B_Sardinian-3 | F16: Sardinian | G16: WestEurasia | H16: Italy | I16: ? | J16: Howard Cann | K16: M | L16: 40 | M16: 9 | N16: Genomic_from_cell_lines | O16: FullyPublic | P16: X | Q16: =VLOOKUP(B16,Tabelle2!C:S,17,0) -> 0
A17: B | B17: SS6004475 | C17: HGDP00936 | D17: HGDP00936 | E17: B_Yoruba-3 | F17: Yoruba | G17: Africa | H17: Nigeria | I17: ? | J17: Howard Cann | K17: M | L17: 7.4 | M17: 3.9 | N17: Genomic_from_cell_lines | O17: FullyPublic | P17: X | Q17: =VLOOKUP(B17,Tabelle2!C:S,17,0) -> 0
A18: C | B18: LP6005677-DNA_B01 | C18: ALB212 | D18: ALB212 | E18: S_Albanian-1 | F18: Albanian | G18: WestEurasia | H18: Albania | I18: Tirana | J18: David Comas | K18: F | L18: 41.3 | M18: 19.8 | N18: Genomic_from_blood | O18: FullyPublic | P18: X | Q18: =VLOOKUP(B18,Tabelle2!C:S,17,0) -> 0
A19: C | B19: LP6005442-DNA_F02 | C19: altai363p | D19: altai363p | E19: S_Altaian-1 | F19: Altaian | G19: CentralAsiaSiberia | H19: Russia | I19: Tenga | Q19: =VLOOKUP(B19,Tabelle2!C:S,17,0) -> 0
A20: C | B20: LP6005442-DNA_E07 | C20: NA13604 | D20: NA13604 | E20: S_Atayal-1 | F20: Atayal | G20: EastAsia | H20: Taiwan | I20: Cell_line_repository_sampling_location_unknown | J20: Coriell | K20: M | L20: 24.611712 | M20: 121.29644 | N20: Genomic_from_cell_lines | O20: FullyPublic | P20: X | Q20: =VLOOKUP(B20,Tabelle2!C:S,17,0) -> 0
A21: C | B21: LP6005519-DNA_D01 | C21: TGBS21 | D21: TGBS21 | E21: S_Chane-1 | F21: Chane | G21: America | H21: Argentina | I21: Salta (province) | Q21: =VLOOKUP(B21,Tabelle2!C:S,17,0) -> 0
A22: C | B22: LP6005442-DNA_D03 | C22: ch113 | D22: ch113 | E22: S_Chechen-1 | F22: Chechen | G22: WestEurasia | H22: Russia | I22: Grozny_in_Chechen_Republic | J22: Mait Metspalu / Elza Khusnutdinova / Rita Khusainova | K22: M | L22: 43.333 | M22: 45.65 | N22: Genomic_from_blood | O22: FullyPublic | P22: X | Q22: =VLOOKUP(B22,Tabelle2!C:S,17,0) -> 0
A23: C | B23: LP6005443-DNA_C03 | C23: Sir19 | D23: Sir19 | E23: S_Chukchi-1 | F23: Chukchi | G23: CentralAsiaSiberia | H23: Russia | I23: Sireniki | Q23: =VLOOKUP(B23,Tabelle2!C:S,17,0) -> 0
A24: C | B24: LP6005443-DNA_H05 | C24: NA15728 | D24: NA15728 | E24: S_Czech-2 | F24: Czech | G24: WestEurasia | H24: Czechoslovia(pre1989) | I24: Cell_line_repository_sampling_location_unknown | J24: Coriell | K24: M | L24: 50.1 | M24: 14.4 | N24: Genomic_from_cell_lines | O24: FullyPublic | P24: X | Q24: =VLOOKUP(B24,Tabelle2!C:S,17,0) -> 0
A25: C | B25: LP6005443-DNA_D03 | C25: Esk29 | D25: Esk29 | E25: S_Eskimo_Chaplin-1 | F25: Eskimo_Chaplin | G25: CentralAsiaSiberia | H25: Russia | I25: New Chaplino | Q25: =VLOOKUP(B25,Tabelle2!C:S,17,0) -> 0
A26: C | B26: LP6005592-DNA_H03 | C26: NA17385 | D26: NA17385 | E26: S_Hawaiian-1 | F26: Hawaiian | G26: Oceania | H26: USA | I26: Cell_line_repository_sampling_location_unknown | J26: Coriell | K26: M | L26: 21.3 | M26: -157.8 | N26: Genomic_from_cell_lines | O26: FullyPublic | P26: X | Q26: =VLOOKUP(B26,Tabelle2!C:S,17,0) -> 0
A27: C | B27: LP6005443-DNA_D04 | C27: Kor82 | D27: Kor82 | E27: S_Itelman-1 | F27: Itelman | G27: CentralAsiaSiberia | H27: Russia | I27: Kovran | Q27: =VLOOKUP(B27,Tabelle2!C:S,17,0) -> 0
A28: C | B28: LP6005519-DNA_E05 | C28: KD4 | D28: KD4 | E28: S_Khonda_Dora-1 | F28: Khonda_Dora | G28: SouthAsia | H28: India | I28: ? | J28: Lynn Jorde / Mike Bamshad / Scott Watkins | K28: M | L28: 18.3 | M28: 82.9 | N28: Genomic_from_blood | O28: FullyPublic | P28: X | Q28: =VLOOKUP(B28,Tabelle2!C:S,17,0) -> 0
A29: C | B29: LP6005592-DNA_B02 | C29: NA17386 | D29: NA17386 | E29: S_Maori-1 | F29: Maori | G29: Oceania | H29: New Zealand | I29: Cell_line_repository_sampling_location_unknown | J29: Coriell | K29: M | L29: -41.3 | M29: 174.5 | N29: Genomic_from_cell_lines | O29: FullyPublic | P29: X | Q29: =VLOOKUP(B29,Tabelle2!C:S,17,0) -> 0
A30: C | B30: LP6005592-DNA_B01 | C30: NOR111 | D30: NOR111 | E30: S_Norwegian-1 | F30: Norwegian | G30: WestEurasia | H30: Norway | I30: Bergen | J30: Cristian Capelli / Tor Hervig | K30: U | L30: 60.4 | M30: 5.4 | N30: Genomic_from_blood | O30: FullyPublic | P30: X | Q30: =VLOOKUP(B30,Tabelle2!C:S,17,0) -> 0
A31: C | B31: LP6005592-DNA_E02 | C31: ND15865 | D31: ND15865 | E31: S_Polish-1 | F31: Polish | G31: WestEurasia | H31: Poland | I31: Cell_line_repository_sampling_location_unknown | J31: Coriell | K31: M | L31: 52.2 | M31: 21 | N31: Genomic_from_cell_lines | O31: FullyPublic | P31: X | Q31: =VLOOKUP(B31,Tabelle2!C:S,17,0) -> 0
A32: C | B32: LP6005592-DNA_D04 | C32: Sam02 | D32: Sam02 | E32: S_Samaritan-1 | F32: Samaritan | G32: WestEurasia | H32: Israel | I32: Mount Gerizim | J32: Mait Metspalu / Doron Behar | K32: M | L32: 32.203 | M32: 35.27 | N32: Genomic_from_blood | O32: FullyPublic | P32: X | Q32: =VLOOKUP(B32,Tabelle2!C:S,17,0) -> 0
A33: C | B33: LP6005442-DNA_D09 | C33: Ayodo_81S | D33: Ayodo_81S | E33: S_Somali-1 | F33: Somali | G33: Africa | H33: Kenya | I33: Garissa | J33: Geoge Ayodo | K33: F | L33: 5.6 | M33: 48.3 | N33: Genomic_from_blood | O33: FullyPublic | P33: X | Q33: =VLOOKUP(B33,Tabelle2!C:S,17,0) -> 0
A34: C | B34: LP6005442-DNA_G02 | C34: armenia293 | D34: armenia293 | E34: S_Armenian-1 | F34: Armenian | G34: WestEurasia | H34: Armenia | I34: Yerevan but all 4 ancestorscome from Nagorno Kharabakh | J34: Mait Metspalu/ Levon Yepiskoposyan / Hovhannes Sahakyan | K34: M | L34: 39.815 | M34: 46.752 | N34: Genomic_from_blood | O34: FullyPublic | P34: X | Q34: =VLOOKUP(B34,Tabelle2!C:S,17,0) -> 0
A35: C | B35: LP6005519-DNA_F03 | C35: Armenian222 | D35: Armenian222 | E35: S_Armenian-2 | F35: Armenian | G35: WestEurasia | H35: Armenia | I35: born in Akhuzyan but all 4 ancestors come from Kars - now Turkey | J35: Mait Metspalu/ Levon Yepiskoposyan / Hovhannes Sahakyan | K35: M | L35: 40.605 | M35: 43.101 | N35: Genomic_from_blood | O35: FullyPublic | P35: X | Q35: =VLOOKUP(B35,Tabelle2!C:S,17,0) -> 0
A36: C | B36: LP6005441-DNA_D01 | C36: HGDP00090 | D36: HGDP00090 | E36: S_Balochi-1 | F36: Balochi | G36: SouthAsia | H36: Pakistan | I36: ? | J36: Howard Cann | K36: M | L36: 30.5 | M36: 66.5 | N36: Genomic_from_cell_lines | O36: FullyPublic | P36: X | Q36: =VLOOKUP(B36,Tabelle2!C:S,17,0) -> 0
A37: C | B37: LP6005441-DNA_C01 | C37: HGDP00058 | D37: HGDP00058 | E37: S_Balochi-2 | F37: Balochi | G37: SouthAsia | H37: Pakistan | I37: ? | J37: Howard Cann | K37: M | L37: 30.498715 | M37: 66.5 | N37: Genomic_from_cell_lines | O37: FullyPublic | P37: X | Q37: =VLOOKUP(B37,Tabelle2!C:S,17,0) -> 0
A38: C | B38: LP6005441-DNA_A06 | C38: HGDP01153 | D38: HGDP01153 | E38: S_Bergamo-1 | F38: Bergamo | G38: WestEurasia | H38: Italy(Bergamo) | I38: ? | J38: Howard Cann | K38: M | L38: 46 | M38: 10 | N38: Genomic_from_cell_lines | O38: FullyPublic | P38: X | Q38: =VLOOKUP(B38,Tabelle2!C:S,17,0) -> 0
A39: C | B39: LP6005441-DNA_B06 | C39: HGDP01172 | D39: HGDP01172 | E39: S_Bergamo-2 | F39: Bergamo | G39: WestEurasia | H39: Italy(Bergamo) | I39: ? | J39: Howard Cann | K39: F | L39: 46 | M39: 10 | N39: Genomic_from_cell_lines | O39: FullyPublic | P39: X | Q39: =VLOOKUP(B39,Tabelle2!C:S,17,0) -> 0
... A59: C | B59: LP6005441-DNA_B01 | C59: HGDP01401 | D59: HGDP01401 | E59: S_Adygei-2 | F59: Adygei | G59: WestEurasia | H59: Russia(Caucasus) | I59: Krasnodar | J59: Howard Cann | K59: F | L59: 44 | M59: 39 | N59: Genomic_from_cell_lines | O59: FullyPublic | P59: X | Q59: =VLOOKUP(B59,Tabelle2!C:S,17,0) -> 0
...

Sheet Tabelle2
A1: # 1-n | B1: 2-ena_id | C1: 3-Illumina_ID | D1: 4-reich_id | E1: 5-ena_ftp_bam_ptr | F1: 6-Sequencing_Panel | G1: 7-Gender | H1: 8-Population_ID | I1: 9-Contributor | J1: 10-Region | K1: 11-Country | L1: 12-Town | M1: 13-Latitude | N1: 14-Longitude | O1: 15-DNA_Source | P1: 16-BioSamples Accession | Q1: 17-Embargo | R1: SampleID
A2: 1 | B2: SAMEA3302859 | C2: LP6005443-DNA_B06 | D2: S_Icelandic-2 | E2: ftp.sra.ebi.ac.uk/vol1/ERZ324/ERZ324295/LP6005443-DNA_B06.srt.aln.bam | F2: C | G2: F | H2: Icelandic | I2: Coriell | J2: WestEurasia | K2: Iceland | L2: Cell_line_repository_sampling_location_unknown | M2: 64.1 | N2: -21.9 | O2: Genomic_from_cell_lines | P2: SAMEA3302859 | Q2: FullyPublic | R2: =VLOOKUP(C2,Tabelle1!B:C,2,0) -> NA15763
A3: 2 | B3: SAMEA3302837 | C3: LP6005442-DNA_D08 | D3: S_Icelandic-1 | E3: ftp.sra.ebi.ac.uk/vol1/ERZ125/ERZ125657/srt.aln.bam | F3: C | G3: F | H3: Icelandic | I3: Coriell | J3: WestEurasia | K3: Iceland | L3: Cell_line_repository_sampling_location_unknown | M3: 64.1 | N3: -21.9 | O3: Genomic_from_cell_lines | P3: SAMEA3302837 | Q3: FullyPublic | R3: =VLOOKUP(C3,Tabelle1!B:C,2,0) -> NA15761
A4: 3 | B4: SAMEA3302616 | C4: LP6005441-DNA_D07 | D4: S_Makrani-2 | E4: ftp.sra.ebi.ac.uk/vol1/ERZ324/ERZ324870/LP6005441-DNA_D07.srt.aln.bam | F4: C | G4: F | H4: Makrani | I4: Howard Cann | J4: SouthAsia | K4: Pakistan | L4: ? | M4: 26 | N4: 64 | O4: Genomic_from_cell_lines | P4: SAMEA3302616 | Q4: FullyPublic | R4: =VLOOKUP(C4,Tabelle1!B:C,2,0) -> HGDP00157
A5: 4 | B5: SAMEA3302771 | C5: LP6005441-DNA_C07 | D5: S_Makrani-1 | E5: ftp.sra.ebi.ac.uk/vol1/ERZ312/ERZ312785/LP6005441-DNA_C07.srt.aln.bam | F5: C | G5: M | H5: Makrani | I5: Howard Cann | J5: SouthAsia | K5: Pakistan | L5: ? | M5: 26 | N5: 64 | O5: Genomic_from_cell_lines | P5: SAMEA3302771 | Q5: FullyPublic | R5: =VLOOKUP(C5,Tabelle1!B:C,2,0) -> HGDP00160
A6: 5 | B6: SAMEA3302647 | C6: LP6005442-DNA_G11 | D6: S_Mende-1 | E6: ftp.sra.ebi.ac.uk/vol1/ERZ324/ERZ324275/LP6005442-DNA_G11.srt.aln.bam | F6: C | G6: M | H6: Mende | I6: 1KG | J6: Africa | K6: SierraLeone | L6: ? | M6: 8.5 | N6: -13.2 | O6: Genomic_from_cell_lines | P6: SAMEA3302647 | Q6: FullyPublic | R6: =VLOOKUP(C6,Tabelle1!B:C,2,0) -> HG03078
A7: 6 | B7: SAMEA3302748 | C7: LP6005442-DNA_H11 | D7: S_Mende-2 | E7: ftp.sra.ebi.ac.uk/vol1/ERZ324/ERZ324282/LP6005442-DNA_H11.srt.aln.bam | F7: C | G7: F | H7: Mende | I7: 1KG | J7: Africa | K7: SierraLeone | L7: ? | M7: 8.5 | N7: -13.2 | O7: Genomic_from_cell_lines | P7: SAMEA3302748 | Q7: FullyPublic | R7: =VLOOKUP(C7,Tabelle1!B:C,2,0) -> HG03085
A8: 7 | B8: SAMEA3302764 | C8: LP6005442-DNA_F12 | D8: S_Tubalar-1 | E8: ftp.sra.ebi.ac.uk/vol1/ERZ324/ERZ324267/LP6005442-DNA_F12.srt.aln.bam | F8: C | G8: F | H8: Tubalar | I8: Rem Sukernik / Stanislav Dryomov | J8: CentralAsiaSiberia | K8: Russia | L8: Artybash and Kebezen, Altai-Sayan Upland | M8: 51.133333 | N8: 87 | O8: Genomic_from_blood | P8: SAMEA3302764 | Q8: FullyPublic | R8: =VLOOKUP(C8,Tabelle1!B:C,2,0) -> Tuba19
A9: 8 | B9: SAMEA3302781 | C9: LP6005442-DNA_E12 | D9: S_Tubalar-2 | E9: ftp.sra.ebi.ac.uk/vol1/ERZ324/ERZ324260/LP6005442-DNA_E12.srt.aln.bam | F9: C | G9: F | H9: Tubalar | I9: Rem Sukernik / Stanislav Dryomov | J9: CentralAsiaSiberia | K9: Russia | L9: Artybash and Kebezen, Altai-Sayan Upland | M9: 51.133333 | N9: 87 | O9: Genomic_from_blood | P9: SAMEA3302781 | Q9: FullyPublic | R9: =VLOOKUP(C9,Tabelle1!B:C,2,0) -> Tuba9
A10: 9 | B10: SAMEA3302703 | C10: LP6005442-DNA_G12 | D10: S_Ulchi-2 | E10: ftp.sra.ebi.ac.uk/vol1/ERZ324/ERZ324276/LP6005442-DNA_G12.srt.aln.bam | F10: C | G10: F | H10: Ulchi | I10: Rem Sukernik / Stanislav Dryomov | J10: CentralAsiaSiberia | K10: Russia | L10: Bogorodskoe, Lower Amur | M10: 52.37 | N10: 140.45 | O10: Genomic_from_blood | P10: SAMEA3302703 | Q10: FullyPublic | R10: =VLOOKUP(C10,Tabelle1!B:C,2,0) -> Ul5
A11: 10 | B11: SAMEA3302862 | C11: LP6005442-DNA_H12 | D11: S_Ulchi-1 | E11: ftp.sra.ebi.ac.uk/vol1/ERZ324/ERZ324283/LP6005442-DNA_H12.srt.aln.bam | F11: C | G11: F | H11: Ulchi | I11: Rem Sukernik / Stanislav Dryomov | J11: CentralAsiaSiberia | K11: Russia | L11: Nizhniy Gavan, Lower Amur | M11: 52.43 | N11: 140.42 | O11: Genomic_from_blood | P11: SAMEA3302862 | Q11: FullyPublic | R11: =VLOOKUP(C11,Tabelle1!B:C,2,0) -> Ul31
A12: 11 | B12: SAMEA3302655 | C12: LP6005442-DNA_C02 | D12: S_Abkhasian-1 | E12: ftp.sra.ebi.ac.uk/vol1/ERZ312/ERZ312844/LP6005442-DNA_C02.srt.aln.bam | F12: C | G12: M | H12: Abkhasian | I12: Mait Metspalu / Elza Khusnutdinova / Rita Khusainova | J12: WestEurasia | K12: Abkhazia | L12: Sukhum | M12: 43.003 | N12: 41.015 | O12: Genomic_from_blood | P12: SAMEA3302655 | Q12: FullyPublic | R12: =VLOOKUP(C12,Tabelle1!B:C,2,0) -> abh107
A13: 12 | B13: SAMEA3302693 | C13: LP6005442-DNA_D02 | D13: S_Abkhasian-2 | E13: ftp.sra.ebi.ac.uk/vol1/ERZ312/ERZ312765/LP6005442-DNA_D02.srt.aln.bam | F13: C | G13: M | H13: Abkhasian | I13: Mait Metspalu / Elza Khusnutdinova / Rita Khusainova | J13: WestEurasia | K13: Russia | L13: Sukhum | M13: 43.003 | N13: 41.015 | O13: Genomic_from_blood | P13: SAMEA3302693 | Q13: FullyPublic | R13: =VLOOKUP(C13,Tabelle1!B:C,2,0) -> abh100
... A281: 280 | B281: SAMEA3302807 | C281: LP6005592-DNA_G01 | D281: S_Yemenite_Jew-2 | E281: ftp.sra.ebi.ac.uk/vol1/ERZ324/ERZ324392/LP6005592-DNA_G01.srt.aln.bam | F281: C | G281: M | H281: Yemenite_Jew | I281: Tel-Aviv University | J281: WestEurasia | K281: Yemen | L281: Cell_line_repository | M281: 15.4 | N281: 44.2 | O281: Genomic_from_cell_lines | P281: SAMEA3302807 | Q281: FullyPublic | R281: =VLOOKUP(C281,Tabelle1!B:C,2,0) -> YemeniteJew5433
R282: =VLOOKUP(C282,Tabelle1!B:C,2,0) -> #N/A
